# manejo de errores con excepciones
while(True):
    try:
        n = float(input("Introduce un número: "))
        m = 4
        print("{}/{} = {}".format(n,m,n/m))
        break # Importante romper la iteración si todo ha salido bien
    except:
        print("Ha ocurrido un error, introduce bien el número")


while(True):
    try:
        n = float(input("Introduce un número: "))
        m = 4
        print("{}/{} = {}".format(n,m,n/m))
    except:
        print("Ha ocurrido un error, introduce bien el número")
    else:
        print("Todo ha funcionado correctamente")
        break # Importante romper la iteración si todo ha salido bien


while(True):
    try:
        n = float(input("Introduce un número: "))
        m = 4
        print("{}/{} = {}".format(n,m,n/m))
    except:
        print("Ha ocurrido un error, introduce bien el número")
    else:
        print("Todo ha funcionado correctamente")
        break # Importante romper la iteración si todo ha salido bien
    finally:
        print("Fin de la iteración") # Siempre se ejecuta



try:
    n = input("Introduce un número: ") # no transformamos a número
    5/n
except Exception as e: # guardamos la excepción como una variable e
    print("Ha ocurrido un error =>", type(e).__name__)


try:
    n = float(input("Introduce un número divisor: "))
    5/n
except TypeError:
    print("No se puede dividir el número entre una cadena")
except ValueError:
    print("Debes introducir una cadena que sea un número")
except ZeroDivisionError:
    print("No se puede dividir por cero, prueba otro número")
except Exception as e:
    print("Ha ocurrido un error no previsto", type(e).__name__ )


def mi_funcion(algo=None):
    try:
        if algo is None:
            raise ValueError("Error! No se permite un valor nulo")
    except ValueError:
        print("Error! No se permite un valor nulo (desde la excepción)")

mi_funcion()